<?xml version="1.0" ?>
<sdf version="1.5">
        <model name="ostrich">
            <pose>0 -2.0 0 0 0 0</pose>
            <static>false</static>
            <link name="h_pelvis">
                <pose> 0.0 1.25 0 0 0 0</pose>
                <inertial>
                    <mass>3.52</mass>
                </inertial>
                <visual>
                    <pose>0.0 0 0.0 1.57079632679 0 0</pose>
                    <geometry>
                        <cylinder>
                            <length>0.4</length>
                            <radius>0.05</radius>
                        </cylinder>
                    </geometry>
                </visual>
                <collision>
                    <pose>0.0 0 0.0 1.57079632679 0 0</pose>
                    <geometry>
                        <cylinder>
                            <length>0.4</length>
                            <radius>0.05</radius>
                        </cylinder>
                    </geometry>
                </collision>
            </link>

            <link name="h_pelvis_aux">
                <pose> 0.0 1.25 0 0 0 0</pose>
                <inertial>
                    <mass>0.000001</mass>
                </inertial>
            </link>

            <link name="h_pelvis_aux2">
                <pose> 0.0 1.25 0 0 0 0</pose>
                <inertial>
                    <mass>0.000001</mass>
                </inertial>
            </link>

            <!-- Right Leg -->
            <link name="h_thigh">
                <pose>0.0 1.00 0.0 0.0 0.0 0.0</pose>
                <inertial>
                    <mass>3.92699082</mass>
                </inertial>
                <visual>
                    <pose>0.0 -0.1 0.0 1.57079632679 0.0 0.0</pose>
                    <geometry>
                        <cylinder>
                            <length>0.20</length>
                            <radius>0.05</radius>
                        </cylinder>
                    </geometry>
                </visual>
                <collision>
                    <pose>0.0 -0.1 0.0 1.57079632679 0.0 0.0</pose>
                    <geometry>
                        <cylinder>
                            <length>0.20</length>
                            <radius>0.05</radius>
                        </cylinder>
                    </geometry>
                </collision>
            </link>

            <link name="h_shin">
                <pose>0.0 0.75 0.0 0.0 0.0 0.0</pose>
                <inertial>
                    <mass>2.71433605</mass>
                </inertial>
                <visual>
                    <pose>0.0 -0.2 0.0 1.57079632679 0.0 0.0</pose>
                    <geometry>
                        <cylinder>
                            <length>0.4</length>
                            <radius>0.04</radius>
                        </cylinder>
                    </geometry>
                </visual>
                <collision>
                    <pose>0.0 -0.2 0.0 1.57079632679 0.0 0.0</pose>
                    <geometry>
                        <cylinder>
                            <length>0.3</length>
                            <radius>0.04</radius>
                        </cylinder>
                    </geometry>
                </collision>
            </link>

            <link name="h_foot">
                <pose>0.0 0.30 0.0 0.0 0.0 0.0</pose>
                <inertial>
                    <mass>2.71433605</mass>
                </inertial>
                <visual>
                    <pose>0.0 -0.2 0.0 1.57079632679 0.0 0.0</pose>
                    <geometry>
                        <cylinder>
                            <length>0.4</length>
                            <radius>0.04</radius>
                        </cylinder>
                    </geometry>
<!--                    <color>1.0 0.5 0.0</color>-->
                </visual>
                <collision>
                    <pose>0.0 -0.2 0.0 1.57079632679 0.0 0.0</pose>
                    <geometry>
                        <cylinder>
                            <length>0.3</length>
                            <radius>0.04</radius>
                        </cylinder>
                    </geometry>
                </collision>
            </link>

            <link name="h_atoe">
                <pose>0.0 -0.1 0.0 0.0 0.0 0.0</pose>
                <inertial>
                    <mass>2.94053072</mass>
                </inertial>
                <visual>
                    <pose>0.1 0.0 0.0 0.0 1.57079632679 0.0</pose>
                    <geometry>
                        <cylinder>
                            <length>0.2</length>
                            <radius>0.06</radius>
                        </cylinder>
                    </geometry>
                    <color>1.0 1.0 0.0</color>
                    <material>
                        <diffuse>1.0 1.0 0.0</diffuse>
                    </material>
                </visual>
                <collision>
                    <pose>0.1 0.0 0.0 0.0 1.57079632679 0.0</pose>
                    <geometry>
                        <cylinder>
                            <length>0.2</length>
                            <radius>0.06</radius>
                        </cylinder>
                    </geometry>
                </collision>
            </link>

            <!-- Left Leg -->
            <link name="h_thigh_left">
                <pose>0.0 1.00 0.0 0.0 0.0 0.0</pose>
                <inertial>
                    <mass>3.92699082</mass>
                </inertial>
                <visual>
                    <pose>0.0 -0.1 0.0 1.57079632679 0.0 0.0</pose>
                    <geometry>
                        <cylinder>
                            <length>0.20</length>
                            <radius>0.05</radius>
                        </cylinder>
                    </geometry>
                    <color>1.0 0.0 1.0</color>
                    <material>
                        <diffuse>1.0 0.0 1.0</diffuse>
                    </material>

                </visual>
                <collision>
                    <pose>0.0 -0.1 0.0 1.57079632679 0.0 0.0</pose>
                    <geometry>
                        <cylinder>
                            <length>0.20</length>
                            <radius>0.05</radius>
                        </cylinder>
                    </geometry>
                </collision>
            </link>

            <link name="h_shin_left">
                <pose>0.0 0.75 0.0 0.0 0.0 0.0</pose>
                <inertial>
                    <mass>2.71433605</mass>
                </inertial>
                <visual>
                    <pose>0.0 -0.2 0.0 1.57079632679 0.0 0.0</pose>
                    <geometry>
                        <cylinder>
                            <length>0.4</length>
                            <radius>0.04</radius>
                        </cylinder>
                    </geometry>
                    <color>1.0 0.0 1.0</color>
                    <material>
                        <diffuse>1.0 0.0 1.0</diffuse>
                    </material>

                </visual>
                <collision>
                    <pose>0.0 -0.2 0.0 1.57079632679 0.0 0.0</pose>
                    <geometry>
                        <cylinder>
                            <length>0.3</length>
                            <radius>0.04</radius>
                        </cylinder>
                    </geometry>
                </collision>
            </link>

            <link name="h_foot_left">
                <pose>0.0 0.30 0.0 0.0 0.0 0.0</pose>
                <inertial>
                    <mass>2.71433605</mass>
                </inertial>
                <visual>
                    <pose>0.0 -0.2 0.0 1.57079632679 0.0 0.0</pose>
                    <geometry>
                        <cylinder>
                            <length>0.4</length>
                            <radius>0.04</radius>
                        </cylinder>
                    </geometry>
                    <color>1.0 0.0 1.0</color>
                    <material>
                        <diffuse>1.0 0.0 1.0</diffuse>
                    </material>

                </visual>
                <collision>
                    <pose>0.0 -0.2 0.0 1.57079632679 0.0 0.0</pose>
                    <geometry>
                        <cylinder>
                            <length>0.3</length>
                            <radius>0.04</radius>
                        </cylinder>
                    </geometry>
                </collision>
            </link>

            <link name="h_atoe_left">
                <pose>0.0 -0.1 0.0 0.0 0.0 0.0</pose>
                <inertial>
                    <mass>2.94053072</mass>
                </inertial>
                <visual>
                    <pose>0.1 0.0 0.0 0.0 1.57079632679 0.0</pose>
                    <geometry>
                        <cylinder>
                            <length>0.2</length>
                            <radius>0.06</radius>
                        </cylinder>
                    </geometry>
                    <color>1.0 0.0 1.0</color>
                    <material>
                        <diffuse>1.0 0.0 1.0</diffuse>
                    </material>

                </visual>
                <collision>
                    <pose>0.1 0.0 0.0 0.0 1.57079632679 0.0</pose>
                    <geometry>
                        <cylinder>
                            <length>0.2</length>
                            <radius>0.06</radius>
                        </cylinder>
                    </geometry>
                </collision>
            </link>



            <!-- JOINT: Pelvis -->
            <joint type="prismatic" name="j_pelvis_x">
                <parent>world</parent>
                <child>h_pelvis_aux2</child>
                <axis>
                      <xyz>1.0 0.0 0.0</xyz>
                </axis>
            </joint>

            <joint type="prismatic" name="j_pelvis_y">
                <parent>h_pelvis_aux2</parent>
                <child>h_pelvis_aux</child>
                <axis>
                      <xyz>0.0 1.0 0.0</xyz>
                </axis>
            </joint>

            <joint type="revolute" name="j_pelvis_rot">
                <parent>h_pelvis_aux</parent>
                <child>h_pelvis</child>
                <axis>
                      <xyz>0.0 0.0 1.0</xyz>
                </axis>
            </joint>


            <!-- JOINT: Leg -->
            <joint type="revolute" name="j_thigh">
                <pose>0.0 0.0 0.0 0.0 0.0 0.0</pose>
                <parent>h_pelvis</parent>
                <child>h_thigh</child>
                <axis>
                    <xyz>0.0 0.0 1.0</xyz>
		     <limit>
                    	<lower>-0.785</lower>
                    	<upper>1.57</upper>
                    </limit>
                    <dynamics>
                        <damping>1.0</damping>
                        <friction>0.0</friction>
                    </dynamics>
                </axis>
            </joint>

            <joint type="revolute" name="j_shin">
                <pose>0.0 0.0 0.0 0.0 0.0 0.0</pose>
                <parent>h_thigh</parent>
                <child>h_shin</child>
                <axis>
                    <xyz>0.0 0.0 1.0</xyz>
		     <limit>
                    	<lower>-2.61799</lower>
                    	<upper>0.0</upper>
                    </limit>
                    <dynamics>
                        <damping>1.0</damping>
                        <friction>0.0</friction>
                    </dynamics>
                </axis>
            </joint>

            <joint type="revolute" name="j_foot">
                <pose>0.0 0.0 0.0 0.0 0.0 0.0</pose>
                <parent>h_shin</parent>
                <child>h_foot</child>
                <axis>
                    <xyz>0.0 0.0 1.0</xyz>
		     <limit>
                    	<lower>0.0</lower>
                    	<upper>2.61799</upper>
                    </limit>
                    <dynamics>
                        <damping>1.0</damping>
                        <friction>0.0</friction>
                    </dynamics>
                </axis>
            </joint>

            <joint type="revolute" name="j_atoe">
                <pose>0.0 0.0 0.0 0.0 0.0 0.0</pose>
                <parent>h_foot</parent>
                <child>h_atoe</child>
                <axis>
                    <xyz>0.0 0.0 1.0</xyz>
    		     <limit>
                    	<lower>-1.570796</lower>
                    	<upper>1.570796</upper>
                    </limit>
                    <dynamics>
                        <damping>1.0</damping>
                        <friction>0.0</friction>
                    </dynamics>
                </axis>
            </joint>

            <!-- JOINT: Left Leg -->
            <joint type="revolute" name="j_thigh_left">
                <pose>0.0 0.0 0.0 0.0 0.0 0.0</pose>
                <parent>h_pelvis</parent>
                <child>h_thigh_left</child>
                <axis>
                    <xyz>0.0 0.0 1.0</xyz>
		     <limit>
                    	<lower>-0.785</lower>
                    	<upper>1.57</upper>
                    </limit>
                    <dynamics>
                        <damping>1.0</damping>
                        <friction>0.0</friction>
                    </dynamics>
                </axis>
            </joint>

            <joint type="revolute" name="j_shin_left">
                <pose>0.0 0.0 0.0 0.0 0.0 0.0</pose>
                <parent>h_thigh_left</parent>
                <child>h_shin_left</child>
                <axis>
                    <xyz>0.0 0.0 1.0</xyz>
		     <limit>
                    	<lower>-2.61799</lower>
                    	<upper>0.0</upper>
                    </limit>
                    <dynamics>
                        <damping>1.0</damping>
                        <friction>0.0</friction>
                    </dynamics>
                </axis>
            </joint>

            <joint type="revolute" name="j_foot_left">
                <pose>0.0 0.0 0.0 0.0 0.0 0.0</pose>
                <parent>h_shin_left</parent>
                <child>h_foot_left</child>
                <axis>
                    <xyz>0.0 0.0 1.0</xyz>
		     <limit>
                    	<lower>0.0</lower>
                    	<upper>2.61799</upper>
                    </limit>
                    <dynamics>
                        <damping>1.0</damping>
                        <friction>0.0</friction>
                    </dynamics>
                </axis>
            </joint>

            <joint type="revolute" name="j_atoe_left">
                <pose>0.0 0.0 0.0 0.0 0.0 0.0</pose>
                <parent>h_foot_left</parent>
                <child>h_atoe_left</child>
                <axis>
                    <xyz>0.0 0.0 1.0</xyz>
		     <limit>
                    	<lower>-1.570796</lower>
                    	<upper>1.570796</upper>
                    </limit>
                    <dynamics>
                        <damping>1.0</damping>
                        <friction>0.0</friction>
                    </dynamics>
                </axis>
            </joint>
        </model>
</sdf>

